Workbook

Sheet Frequently Used Hashtags
A3: Count of Hashtags Used | B3: Column Labels
A4: Row Labels | B4: 2024 | C4: 2025 | D4: Grand Total
A5: #EVRevolution | B5: 55 | C5: 23 | D5: 78
A6: #FutureOfDriving | B6: 55 | C6: 29 | D6: 84
A7: #TeslaCoInnovation | B7: 48 | C7: 34 | D7: 82
A8: Grand Total | B8: 158 | C8: 86 | D8: 244

Sheet Post Performance
A3: Average of Enggagement Rate | B3: Column Labels
A4: Row Labels | B4: 2024 | C4: 2025
A5: #EVRevolution | B5: 0.90495866 | C5: 1.0979895
A6: #FutureOfDriving | B6: 0.90915317 | C6: 1.1280849
A7: #TeslaCoInnovation | B7: 1.0249851 | C7: 1.0898925

Sheet Content Performance
A3: Row Labels | B3: Sum of Enggagement Rate
A4: Carousel | B4: 0.20778854
A5: Image | B5: 0.21477408
A6: Reel | B6: 0.17442787
A7: Story | B7: 0.14857752
A8: Text | B8: 0.10883334
A9: Video | B9: 0.14559864
A10: Grand Total | B10: 1

Sheet Engagement uplift during vs. be
A1: Campaign_Name | B1: Start_Date | C1: End_Date | D1: Post ID | E1: Platform | F1: Date | G1: Period of Enggagement | H1: uplift before Campaign | I1: uplift duringcampaign
A2: CybertruckLaunch | B2: 45458 | C2: 45488 | D2: P001 | E2: Twitter | F2: 45649 | G2: =IF(AND(F2>=$B$2,F2<=$C$2),"DURING","BEFORE") -> BEFORE | H2: =AVERAGEIF($G$2:$G$245,"Before",'Preprocced Data'!N2) -> 0.14589367 | I2: =AVERAGEIF($G$2:$G$245,"During", 'Preprocced Data'!N2) -> 0.10798061
A3: CybertruckLaunch | B3: 45458 | C3: 45488 | D3: P002 | E3: Twitter | F3: 45750 | G3: =IF(AND(F3>=$B$2,F3<=$C$2),"DURING","BEFORE") -> BEFORE | H3: =AVERAGEIF($G$2:$G$245,"Before",'Preprocced Data'!N3) -> 0.14409171 | I3: =AVERAGEIF($G$2:$G$245,"During", 'Preprocced Data'!N3) -> 0.13082916
A4: CybertruckLaunch | B4: 45458 | C4: 45488 | D4: P003 | E4: YouTube | F4: 45789 | G4: =IF(AND(F4>=$B$2,F4<=$C$2),"DURING","BEFORE") -> BEFORE | H4: =AVERAGEIF($G$2:$G$245,"Before",'Preprocced Data'!N4) -> 0.13695592 | I4: =AVERAGEIF($G$2:$G$245,"During", 'Preprocced Data'!N4) -> 0.2134361
A5: CybertruckLaunch | B5: 45458 | C5: 45488 | D5: P004 | E5: Instagram | F5: 45516 | G5: =IF(AND(F5>=$B$2,F5<=$C$2),"DURING","BEFORE") -> BEFORE | H5: =AVERAGEIF($G$2:$G$245,"Before",'Preprocced Data'!N5) -> 0.13903028 | I5: =AVERAGEIF($G$2:$G$245,"During", 'Preprocced Data'!N5) -> 0.1945856
A6: ModelYCampaign | B6: 45566 | C6: 45596 | D6: P005 | E6: YouTube | F6: 45469 | G6: =IF(AND(F6>=$B$2,F6<=$C$2),"DURING","BEFORE") -> DURING | H6: =AVERAGEIF($G$2:$G$245,"Before",'Preprocced Data'!N6) -> 0.14340352 | I6: =AVERAGEIF($G$2:$G$245,"During", 'Preprocced Data'!N6) -> 0.14587902
A7: ModelYCampaign | B7: 45566 | C7: 45596 | D7: P006 | E7: Facebook | F7: 45596 | G7: =IF(AND(F7>=$B$2,F7<=$C$2),"DURING","BEFORE") -> BEFORE | H7: =AVERAGEIF($G$2:$G$245,"Before",'Preprocced Data'!N7) -> 0.14235486 | I7: =AVERAGEIF($G$2:$G$245,"During", 'Preprocced Data'!N7) -> 0.16125108
A8: FSDUpdate | B8: 45651 | C8: 45667 | D8: P007 | E8: Twitter | F8: 45467 | G8: =IF(AND(F8>=$B$2,F8<=$C$2),"DURING","BEFORE") -> DURING | H8: =AVERAGEIF($G$2:$G$245,"Before",'Preprocced Data'!N8) -> 0.14357677 | I8: =AVERAGEIF($G$2:$G$245,"During", 'Preprocced Data'!N8) -> 0.14607292
A9: FSDUpdate | B9: 45651 | C9: 45667 | D9: P008 | E9: YouTube | F9: 45486 | G9: =IF(AND(F9>=$B$2,F9<=$C$2),"DURING","BEFORE") -> DURING | H9: =AVERAGEIF($G$2:$G$245,"Before",'Preprocced Data'!N9) -> 0.14499361 | I9: =AVERAGEIF($G$2:$G$245,"During", 'Preprocced Data'!N9) -> 0.13380616
A10: SustainabilityDrive | B10: 45717 | C10: 45747 | D10: P009 | E10: Facebook | F10: 45534 | G10: =IF(AND(F10>=$B$2,F10<=$C$2),"DURING","BEFORE") -> BEFORE | H10: =AVERAGEIF($G$2:$G$245,"Before",'Preprocced Data'!N10) -> 0.14635255 | I10: =AVERAGEIF($G$2:$G$245,"During", 'Preprocced Data'!N10) -> 0.12047458
A11: SustainabilityDrive | B11: 45717 | C11: 45747 | D11: P010 | E11: Facebook | F11: 45727 | G11: =IF(AND(F11>=$B$2,F11<=$C$2),"DURING","BEFORE") -> BEFORE | H11: =AVERAGEIF($G$2:$G$245,"Before",'Preprocced Data'!N11) -> 0.14638154 | I11: =AVERAGEIF($G$2:$G$245,"During", 'Preprocced Data'!N11) -> 0.12321512
A12: SustainabilityDrive | B12: 45717 | C12: 45747 | D12: P011 | E12: Instagram | F12: 45690 | G12: =IF(AND(F12>=$B$2,F12<=$C$2),"DURING","BEFORE") -> BEFORE | H12: =AVERAGEIF($G$2:$G$245,"Before",'Preprocced Data'!N12) -> 0.14461208 | I12: =AVERAGEIF($G$2:$G$245,"During", 'Preprocced Data'!N12) -> 0.14715351
A13: SustainabilityDrive | B13: 45717 | C13: 45747 | D13: P012 | E13: Facebook | F13: 45494 | G13: =IF(AND(F13>=$B$2,F13<=$C$2),"DURING","BEFORE") -> BEFORE | H13: =AVERAGEIF($G$2:$G$245,"Before",'Preprocced Data'!N13) -> 0.14577844 | I13: =AVERAGEIF($G$2:$G$245,"During", 'Preprocced Data'!N13) -> 0.13553759
D14: P013 | E14: YouTube | F14: 45614 | G14: =IF(AND(F14>=$B$2,F14<=$C$2),"DURING","BEFORE") -> BEFORE | H14: =AVERAGEIF($G$2:$G$245,"Before",'Preprocced Data'!N14) -> 0.14330898 | I14: =AVERAGEIF($G$2:$G$245,"During", 'Preprocced Data'!N14) -> 0.16411227
D15: P015 | E15: Facebook | F15: 45589 | G15: =IF(AND(F15>=$B$2,F15<=$C$2),"DURING","BEFORE") -> BEFORE | H15: =AVERAGEIF($G$2:$G$245,"Before",'Preprocced Data'!N15) -> 0.14662159 | I15: =AVERAGEIF($G$2:$G$245,"During", 'Preprocced Data'!N15) -> 0.13070008
D16: P016 | E16: Facebook | F16: 45530 | G16: =IF(AND(F16>=$B$2,F16<=$C$2),"DURING","BEFORE") -> BEFORE | H16: =AVERAGEIF($G$2:$G$245,"Before",'Preprocced Data'!N16) -> 0.14821772 | I16: =AVERAGEIF($G$2:$G$245,"During", 'Preprocced Data'!N16) -> 0.11756446
D17: P017 | E17: Facebook | F17: 45782 | G17: =IF(AND(F17>=$B$2,F17<=$C$2),"DURING","BEFORE") -> BEFORE | H17: =AVERAGEIF($G$2:$G$245,"Before",'Preprocced Data'!N17) -> 0.14759397 | I17: =AVERAGEIF($G$2:$G$245,"During", 'Preprocced Data'!N17) -> 0.12826771
D18: P018 | E18: Instagram | F18: 45523 | G18: =IF(AND(F18>=$B$2,F18<=$C$2),"DURING","BEFORE") -> BEFORE | H18: =AVERAGEIF($G$2:$G$245,"Before",'Preprocced Data'!N18) -> 0.14805955 | I18: =AVERAGEIF($G$2:$G$245,"During", 'Preprocced Data'!N18) -> 0.12595472
D19: P019 | E19: Instagram | F19: 45466 | G19: =IF(AND(F19>=$B$2,F19<=$C$2),"DURING","BEFORE") -> DURING | H19: =AVERAGEIF($G$2:$G$245,"Before",'Preprocced Data'!N19) -> 0.14506828 | I19: =AVERAGEIF($G$2:$G$245,"During", 'Preprocced Data'!N19) -> 0.16107421
D20: P020 | E20: Instagram | F20: 45544 | G20: =IF(AND(F20>=$B$2,F20<=$C$2),"DURING","BEFORE") -> BEFORE | H20: =AVERAGEIF($G$2:$G$245,"Before",'Preprocced Data'!N20) -> 0.15057162 | I20: =AVERAGEIF($G$2:$G$245,"During", 'Preprocced Data'!N20) -> 0.10347081
D21: P021 | E21: Instagram | F21: 45661 | G21: =IF(AND(F21>=$B$2,F21<=$C$2),"DURING","BEFORE") -> BEFORE | H21: =AVERAGEIF($G$2:$G$245,"Before",'Preprocced Data'!N21) -> 0.14479307 | I21: =AVERAGEIF($G$2:$G$245,"During", 'Preprocced Data'!N21) -> 0.17068884
D22: P022 | E22: Facebook | F22: 45715 | G22: =IF(AND(F22>=$B$2,F22<=$C$2),"DURING","BEFORE") -> BEFORE | H22: =AVERAGEIF($G$2:$G$245,"Before",'Preprocced Data'!N22) -> 0.14743565 | I22: =AVERAGEIF($G$2:$G$245,"During", 'Preprocced Data'!N22) -> 0.14573175
D23: P023 | E23: Facebook | F23: 45602 | G23: =IF(AND(F23>=$B$2,F23<=$C$2),"DURING","BEFORE") -> BEFORE | H23: =AVERAGEIF($G$2:$G$245,"Before",'Preprocced Data'!N23) -> 0.1495261 | I23: =AVERAGEIF($G$2:$G$245,"During", 'Preprocced Data'!N23) -> 0.12682068
D24: P024 | E24: Facebook | F24: 45680 | G24: =IF(AND(F24>=$B$2,F24<=$C$2),"DURING","BEFORE") -> BEFORE | H24: =AVERAGEIF($G$2:$G$245,"Before",'Preprocced Data'!N24) -> 0.14584532 | I24: =AVERAGEIF($G$2:$G$245,"During", 'Preprocced Data'!N24) -> 0.16997098
D25: P026 | E25: YouTube | F25: 45752 | G25: =IF(AND(F25>=$B$2,F25<=$C$2),"DURING","BEFORE") -> BEFORE | H25: =AVERAGEIF($G$2:$G$245,"Before",'Preprocced Data'!N25) -> 0.15040568 | I25: =AVERAGEIF($G$2:$G$245,"During", 'Preprocced Data'!N25) -> 0.12537006
... D245: P300 | E245: Twitter | F245: 45535 | G245: =IF(AND(F245>=$B$2,F245<=$C$2),"DURING","BEFORE") -> BEFORE | H245: =AVERAGEIF($G$2:$G$245,"Before",'Preprocced Data'!N245) -> 0.083539958 | I245: =AVERAGEIF($G$2:$G$245,"During", 'Preprocced Data'!N245) -> #DIV/0!

Sheet  Conten type PrioritiesPlatform
A3: Count of Content Type | B3: Column Labels
A4: Row Labels | B4: Facebook | C4: Instagram | D4: Twitter | E4: YouTube
A5: Carousel | B5: 12 | C5: 12 | D5: 14 | E5: 10
A6: Image | B6: 23 | C6: 10 | D6: 13 | E6: 7
A7: Reel | B7: 9 | C7: 12 | D7: 9 | E7: 9
A8: Story | B8: 7 | C8: 12 | D8: 8 | E8: 9
A9: Text | B9: 10 | C9: 8 | D9: 10 | E9: 5
A10: Video | B10: 6 | C10: 10 | D10: 11 | E10: 8

Sheet Total and Avg Like and Clicks
A3: Row Labels | B3: Average of Impressions | C3: Average of Clicks2 | D3: Average of Likes | E3: Sum of Likes2 | F3: Sum of Impressions2 | G3: Sum of Clicks
A4: CybertruckLaunch | B4: 38464 | C4: 134.04167 | D4: 2891.5208 | E4: 138793 | F4: 1846272 | G4: 6434
A5: FSDUpdate | B5: 33821.687 | C5: 149.73134 | D5: 2736.5075 | E5: 183346 | F5: 2266053 | G5: 10032
A6: ModelYCampaign | B6: 34247.517 | C6: 170.2069 | D6: 2754.8793 | E6: 159783 | F6: 1986356 | G6: 9872
A7: SustainabilityDrive | B7: 34716.394 | C7: 150.5493 | D7: 2646.6056 | E7: 187909 | F7: 2464864 | G7: 10689

Sheet Preprocced Data
A1: Post ID | B1: Platform | C1: Date | D1: Content Type | E1: Post Text | F1: Likes | G1: Shares | H1: Comments | I1: Impressions | J1: Reach | K1: Clicks | L1: Hashtags Used | M1: Campaign_Name | N1: Enggagement Rate
A2: P001 | B2: Twitter | C2: 45649 | D2: Reel | E2: Check out our latest reel on twitter! | F2: 1461 | G2: 184 | H2: 344 | I2: 21915 | J2: 21675 | K2: 15 | L2: #FutureOfDriving | M2: CybertruckLaunch | N2: =(F2+G2+H2)/I2 -> 0.090759754
A3: P002 | B3: Twitter | C3: 45750 | D3: Text | E3: Check out our latest text on twitter! | F3: 4054 | G3: 389 | H3: 493 | I3: 64864 | J3: 64383 | K3: 117 | L3: #TeslaCoInnovation | M3: ModelYCampaign | N3: =(F3+G3+H3)/I3 -> 0.076097681
A4: P003 | B4: YouTube | C4: 45789 | D4: Reel | E4: Check out our latest reel on youtube! | F4: 2795 | G4: 105 | H4: 49 | I4: 53105 | J4: 52307 | K4: 204 | L4: #TeslaCoInnovation | M4: FSDUpdate | N4: =(F4+G4+H4)/I4 -> 0.055531494
A5: P004 | B5: Instagram | C5: 45516 | D5: Story | E5: Check out our latest story on instagram! | F5: 2404 | G5: 363 | H5: 138 | I5: 19232 | J5: 18636 | K5: 128 | L5: #EVRevolution | M5: SustainabilityDrive | N5: =(F5+G5+H5)/I5 -> 0.15105033
A6: P005 | B6: YouTube | C6: 45469 | D6: Reel | E6: Check out our latest reel on youtube! | F6: 3557 | G6: 687 | H6: 424 | I6: 71140 | J6: 70701 | K6: 224 | L6: #EVRevolution | M6: CybertruckLaunch | N6: =(F6+G6+H6)/I6 -> 0.065617093
A7: P006 | B7: Facebook | C7: 45596 | D7: Carousel | E7: Check out our latest carousel on facebook! | F7: 2945 | G7: 930 | H7: 355 | I7: 23560 | J7: 23275 | K7: 256 | L7: #TeslaCoInnovation | M7: ModelYCampaign | N7: =(F7+G7+H7)/I7 -> 0.1795416
A8: P007 | B8: Twitter | C8: 45467 | D8: Carousel | E8: Check out our latest carousel on twitter! | F8: 3860 | G8: 201 | H8: 279 | I8: 61760 | J8: 61660 | K8: 235 | L8: #TeslaCoInnovation | M8: ModelYCampaign | N8: =(F8+G8+H8)/I8 -> 0.070272021
A9: P008 | B9: YouTube | C9: 45486 | D9: Image | E9: Check out our latest image on youtube! | F9: 3929 | G9: 262 | H9: 278 | I9: 43219 | J9: 42841 | K9: 39 | L9: #EVRevolution | M9: SustainabilityDrive | N9: =(F9+G9+H9)/I9 -> 0.1034036
A10: P009 | B10: Facebook | C10: 45534 | D10: Text | E10: Check out our latest text on facebook! | F10: 3784 | G10: 808 | H10: 404 | I10: 56760 | J10: 56343 | K10: 131 | L10: #TeslaCoInnovation | M10: ModelYCampaign | N10: =(F10+G10+H10)/I10 -> 0.088019732
A11: P010 | B11: Facebook | C11: 45727 | D11: Image | E11: Check out our latest image on facebook! | F11: 4241 | G11: 902 | H11: 47 | I11: 72097 | J11: 71598 | K11: 167 | L11: #TeslaCoInnovation | M11: ModelYCampaign | N11: =(F11+G11+H11)/I11 -> 0.071986352
A12: P011 | B12: Instagram | C12: 45690 | D12: Story | E12: Check out our latest story on instagram! | F12: 1792 | G12: 614 | H12: 497 | I12: 25088 | J12: 24675 | K12: 65 | L12: #FutureOfDriving | M12: SustainabilityDrive | N12: =(F12+G12+H12)/I12 -> 0.11571269
A13: P012 | B13: Facebook | C13: 45494 | D13: Reel | E13: Check out our latest reel on facebook! | F13: 1946 | G13: 686 | H13: 377 | I13: 23352 | J13: 22982 | K13: 213 | L13: #FutureOfDriving | M13: FSDUpdate | N13: =(F13+G13+H13)/I13 -> 0.12885406
... A245: P300 | B245: Twitter | C245: 45535 | D245: Carousel | E245: Check out our latest carousel on twitter! | F245: 4494 | G245: 717 | H245: 45 | I245: 62916 | J245: 62688 | K245: 191 | L245: #TeslaCoInnovation | M245: CybertruckLaunch | N245: =(F245+G245+H245)/I245 -> 0.083539958

Sheet Top 10
A3: Row Labels | B3: Sum of Enggagement Rate
A4: P058 | B4: 0.86601942
A5: P232 | B5: 0.71686747
A6: P178 | B6: 0.70387597
A7: P175 | B7: 0.6508216
A8: P062 | B8: 0.53773585
A9: P264 | B9: 0.53389831
A10: P143 | B10: 0.50192308
A11: P210 | B11: 0.48518408
A12: P214 | B12: 0.37955854
A13: P102 | B13: 0.35666667

Sheet Platform and content type like
A3: Row Labels | B3: Sum of Likes | C3: Sum of Shares | D3: Sum of Comments
A4: Facebook | B4: 196824 | C4: 32470 | D4: 19364
A5: Carousel | B5: 37929 | C5: 6700 | D5: 3764
A6: Image | B6: 63432 | C6: 11344 | D6: 6088
A7: Reel | B7: 28595 | C7: 4763 | D7: 3071
A8: Story | B8: 19598 | C8: 3587 | D8: 2355
A9: Text | B9: 25983 | C9: 3882 | D9: 2680
A10: Video | B10: 21287 | C10: 2194 | D10: 1406
A11: Instagram | B11: 167318 | C11: 34186 | D11: 14079
A12: Carousel | B12: 27350 | C12: 5093 | D12: 2498
A13: Image | B13: 34202 | C13: 5286 | D13: 2655
A14: Reel | B14: 30178 | C14: 7435 | D14: 2908
A15: Story | B15: 35473 | C15: 6932 | D15: 2859
... A31: Video | B31: 28425 | C31: 5022 | D31: 2144

Sheet Top Hashtags
A3: Row Labels | B3: Count of Post ID | C3: Sum of Enggagement Rate
A4: #EVRevolution | B4: 78 | C4: 0.3074856
A5: #FutureOfDriving | B5: 84 | C5: 0.33900773
A6: #TeslaCoInnovation | B6: 82 | C6: 0.35350668
A7: Grand Total | B7: 244 | C7: 1

Sheet Highest Enggagement Rate
A3: Row Labels | B3: Sum of Enggagement Rate
A4: Facebook | B4: 0.22562743
A5: Instagram | B5: 0.32527246
A6: Twitter | B6: 0.2809954
A7: YouTube | B7: 0.16810472
A8: Grand Total | B8: 1

Sheet Raw Given Data
A1: Post ID | B1: Platform | C1: Date | D1: Content Type | E1: Post Text | F1: Likes | G1: Shares | H1: Comments | I1: Impressions | J1: Reach | K1: Clicks | L1: Hashtags Used | M1: Campaign_Name
A2: P001 | B2: Twitter | C2: 2024-12-23 | D2: Reel | E2: Check out our latest reel on twitter! | F2: 1461 | G2: 184 | H2: 344 | I2: 21915 | J2: 21675 | K2: 15 | L2: #FutureOfDriving,#AnytimeIsTeslaTime | M2: CybertruckLaunch
A3: P002 | B3: Twitter | C3: 2025-04-03 | D3: Text | E3: Check out our latest text on twitter! | F3: 4054 | G3: 389 | H3: 493 | I3: 64864 | J3: 64383 | K3: 117 | L3: #TeslaCoInnovation,#BetterWithTesla | M3: ModelYCampaign
A4: P003 | B4: YouTube | C4: 2025-05-12 | D4: Reel | E4: Check out our latest reel on youtube! | F4: 2795 | G4: 105 | H4: 49 | I4: 53105 | J4: 52307 | K4: 204 | L4: #TeslaCoInnovation | M4: FSDUpdate
A5: P004 | B5: Instagram | C5: 2024-08-12 | D5: Story | E5: Check out our latest story on instagram! | F5: 2404 | G5: 363 | H5: 138 | I5: 19232 | J5: 18636 | K5: 128 | L5: #EVRevolution | M5: SustainabilityDrive
A6: P005 | B6: YouTube | C6: 2024-06-26 | D6: Reel | E6: Check out our latest reel on youtube! | F6: 3557 | G6: 687 | H6: 424 | I6: 71140 | J6: 70701 | K6: 224 | L6: #EVRevolution,#TeslaCoInnovation | M6: CybertruckLaunch
A7: P006 | B7: Facebook | C7: 2024-10-31 | D7: Carousel | E7: Check out our latest carousel on facebook! | F7: 2945 | G7: 930 | H7: 355 | I7: 23560 | J7: 23275 | K7: 256 | L7: #TeslaCoInnovation | M7: ModelYCampaign
A8: P007 | B8: Twitter | C8: 2024-06-24 | D8: Carousel | E8: Check out our latest carousel on twitter! | F8: 3860 | G8: 201 | H8: 279 | I8: 61760 | J8: 61660 | K8: 235 | L8: #TeslaCoInnovation | M8: ModelYCampaign
A9: P008 | B9: YouTube | C9: 2024-07-13 | D9: Image | E9: Check out our latest image on youtube! | F9: 3929 | G9: 262 | H9: 278 | I9: 43219 | J9: 42841 | K9: 39 | L9: #EVRevolution | M9: SustainabilityDrive
A10: P009 | B10: Facebook | C10: 2024-08-30 | D10: Text | E10: Check out our latest text on facebook! | F10: 3784 | G10: 808 | H10: 404 | I10: 56760 | J10: 56343 | K10: 131 | L10: #TeslaCoInnovation | M10: ModelYCampaign
A11: P010 | B11: Facebook | C11: 2025-03-11 | D11: Image | E11: Check out our latest image on facebook! | F11: 4241 | G11: 902 | H11: 47 | I11: 72097 | J11: 71598 | K11: 167 | L11: #TeslaCoInnovation | M11: ModelYCampaign
A12: P011 | B12: Instagram | C12: 2025-02-02 | D12: Story | E12: Check out our latest story on instagram! | F12: 1792 | G12: 614 | H12: 497 | I12: 25088 | J12: 24675 | K12: 65 | L12: #FutureOfDriving | M12: SustainabilityDrive
A13: P012 | B13: Facebook | C13: 2024-07-21 | D13: Reel | E13: Check out our latest reel on facebook! | F13: 1946 | G13: 686 | H13: 377 | I13: 23352 | J13: 22982 | K13: 213 | L13: #FutureOfDriving | M13: FSDUpdate
A14: P013 | B14: YouTube | C14: 2024-11-18 | D14: Carousel | E14: Check out our latest carousel on youtube! | F14: 1171 | G14: 286 | H14: 231 | I14: 22249 | J14: 21282 | K14: 114 | L14: #EVRevolution | M14: CybertruckLaunch
A15: P014 | B15: Facebook | C15: 2025-02-16 | D15: Story | E15: Check out our latest story on facebook! | F15: 4242 | G15: 555 | H15: 131 | I15: 33936 | J15: 33802 | K15: 265 | L15: #FutureOfDriving
A16: P015 | B16: Facebook | C16: 2024-10-24 | D16: Video | E16: Check out our latest video on facebook! | F16: 3888 | G16: 604 | H16: 128 | I16: 77760 | J16: 77167 | K16: 20 | L16: #FutureOfDriving | M16: CybertruckLaunch
A17: P016 | B17: Facebook | C17: 2024-08-26 | D17: Text | E17: Check out our latest text on facebook! | F17: 3452 | G17: 377 | H17: 360 | I17: 55232 | J17: 55075 | K17: 87 | L17: #FutureOfDriving | M17: FSDUpdate
A18: P017 | B18: Facebook | C18: 2025-05-05 | D18: Text | E18: Check out our latest text on facebook! | F18: 4441 | G18: 511 | H18: 70 | I18: 53292 | J18: 53082 | K18: 159 | L18: #EVRevolution | M18: SustainabilityDrive
A19: P018 | B19: Instagram | C19: 2024-08-19 | D19: Reel | E19: Check out our latest reel on instagram! | F19: 3000 | G19: 382 | H19: 325 | I19: 36000 | J19: 35819 | K19: 19 | L19: #FutureOfDriving | M19: CybertruckLaunch
A20: P019 | B20: Instagram | C20: 2024-06-23 | D20: Video | E20: Check out our latest video on instagram! | F20: 1071 | G20: 519 | H20: 22 | I20: 16065 | J20: 15865 | K20: 103 | L20: #TeslaCoInnovation | M20: SustainabilityDrive
A21: P020 | B21: Instagram | C21: 2024-09-09 | D21: Carousel | E21: Check out our latest carousel on instagram! | F21: 4054 | G21: 488 | H21: 373 | I21: 77026 | J21: 76881 | K21: 25 | L21: #TeslaCoInnovation | M21: CybertruckLaunch
A22: P021 | B22: Instagram | C22: 2025-01-04 | D22: Reel | E22: Check out our latest reel on instagram! | F22: 4838 | G22: 640 | H22: 128 | I22: 72570 | J22: 72396 | K22: 83 | L22: #FutureOfDriving | M22: SustainabilityDrive
A23: P022 | B23: Facebook | C23: 2025-02-27 | D23: Text | E23: Check out our latest text on facebook! | F23: 1570 | G23: 187 | H23: 260 | I23: 25120 | J23: 24613 | K23: 133 | L23: #TeslaCoInnovation | M23: SustainabilityDrive
A24: P023 | B24: Facebook | C24: 2024-11-06 | D24: Video | E24: Check out our latest video on facebook! | F24: 1606 | G24: 547 | H24: 316 | I24: 32120 | J24: 31736 | K24: 225 | L24: #TeslaCoInnovation,#AnytimeIsTeslaTime | M24: ModelYCampaign
A25: P024 | B25: Facebook | C25: 2025-01-23 | D25: Video | E25: Check out our latest video on facebook! | F25: 3961 | G25: 761 | H25: 131 | I25: 67337 | J25: 66615 | K25: 161 | L25: #FutureOfDriving | M25: FSDUpdate
A26: P025 | B26: Twitter | C26: 2025-04-10 | D26: Carousel | E26: Check out our latest carousel on twitter! | F26: 3128 | G26: 211 | H26: 197 | I26: 59432 | J26: 59182 | K26: 238 | L26: #EVRevolution
A27: P026 | B27: YouTube | C27: 2025-04-05 | D27: Reel | E27: Check out our latest reel on youtube! | F27: 3009 | G27: 413 | H27: 358 | I27: 42126 | J27: 41309 | K27: 211 | L27: #FutureOfDriving | M27: ModelYCampaign
A28: P027 | B28: YouTube | C28: 2024-09-17 | D28: Text | E28: Check out our latest text on youtube! | F28: 2076 | G28: 195 | H28: 104 | I28: 33216 | J28: 32244 | K28: 51 | L28: #FutureOfDriving | M28: SustainabilityDrive
A29: P028 | B29: Instagram | C29: 2025-03-04 | D29: Video | E29: Check out our latest video on instagram! | F29: 432 | G29: 624 | H29: 123 | I29: 6912 | J29: 6259 | K29: 79 | L29: #FutureOfDriving | M29: SustainabilityDrive
A30: P029 | B30: Instagram | C30: 2025-01-31 | D30: Carousel | E30: Check out our latest carousel on instagram! | F30: 2566 | G30: 118 | H30: 37 | I30: 12830 | J30: 12264 | K30: 221 | L30: #FutureOfDriving | M30: FSDUpdate
A31: P030 | B31: Instagram | C31: 2025-02-25 | D31: Video | E31: Check out our latest video on instagram! | F31: 3095 | G31: 39 | H31: 78 | I31: 55710 | J31: 54808 | K31: 93 | L31: #EVRevolution
A32: P031 | B32: Instagram | C32: 2024-12-16 | D32: Text | E32: Check out our latest text on instagram! | F32: 438 | G32: 153 | H32: 275 | I32: 3066 | J32: 2701 | K32: 282 | L32: #TeslaCoInnovation | M32: ModelYCampaign
A33: P032 | B33: Twitter | C33: 2024-07-31 | D33: Carousel | E33: Check out our latest carousel on twitter! | F33: 2278 | G33: 10 | H33: 321 | I33: 13668 | J33: 12676 | K33: 275 | L33: #EVRevolution | M33: CybertruckLaunch
A34: P033 | B34: Facebook | C34: 2024-08-21 | D34: Image | E34: Check out our latest image on facebook! | F34: 1407 | G34: 400 | H34: 351 | I34: 16884 | J34: 15954 | K34: 113 | L34: #TeslaCoInnovation | M34: CybertruckLaunch
A35: P034 | B35: Facebook | C35: 2025-03-26 | D35: Text | E35: Check out our latest text on facebook! | F35: 1652 | G35: 89 | H35: 357 | I35: 29736 | J35: 28771 | K35: 215 | L35: #TeslaCoInnovation | M35: FSDUpdate
A36: P035 | B36: Instagram | C36: 2024-11-30 | D36: Video | E36: Check out our latest video on instagram! | F36: 3775 | G36: 16 | H36: 239 | I36: 33975 | J36: 33310 | K36: 271 | L36: #FutureOfDriving | M36: ModelYCampaign
A37: P036 | B37: Instagram | C37: 2025-04-19 | D37: Story | E37: Check out our latest story on instagram! | F37: 4518 | G37: 285 | H37: 383 | I37: 67770 | J37: 67621 | K37: 31 | L37: #EVRevolution | M37: ModelYCampaign
A38: P037 | B38: Facebook | C38: 2025-01-06 | D38: Carousel | E38: Check out our latest carousel on facebook! | F38: 3024 | G38: 925 | H38: 350 | I38: 24192 | J38: 23518 | K38: 36 | L38: #EVRevolution | M38: ModelYCampaign
A39: P038 | B39: YouTube | C39: 2025-02-17 | D39: Reel | E39: Check out our latest reel on youtube! | F39: 3138 | G39: 123 | H39: 291 | I39: 28242 | J39: 27550 | K39: 87 | L39: #TeslaCoInnovation | M39: SustainabilityDrive
A40: P039 | B40: Facebook | C40: 2024-11-25 | D40: Image | E40: Check out our latest image on facebook! | F40: 3564 | G40: 629 | H40: 177 | I40: 60588 | J40: 59627 | K40: 92 | L40: #TeslaCoInnovation
...

Sheet Followers Growth Rate
A3: Row Labels | B3: Sum of Growth Rate
A4: Facebook | B4: 0.18274442
A5: Instagram | B5: 0.19006667
A6: Twitter | B6: 0.32032253
A7: YouTube | B7: 0.30686638
A8: Grand Total | B8: 1

Sheet Enggagement Rate Vs Ad.Spend
A3: Row Labels | B3: Sum of Ad_Spend | C3: Sum of Engagement_Rate
A4: Facebook | B4: 1379539 | C4: 0.25017273
A5: Instagram | B5: 1164373 | C5: 0.25314011
A6: Twitter | B6: 1060357 | C6: 0.25049161
A7: YouTube | B7: 1228647 | C7: 0.24619555
A8: Grand Total | B8: 4832916 | C8: 1

Sheet Weekly follower growth per plat
A3: Row Labels | B3: Sum of Growth Rate | C3: Sum of New_Followers
A4: Facebook | B4: 0.03542457 | C4: 2576
A5: 2024-07-01 | B5: 0.0028890264 | C5: 505
A6: 2024-07-08 | B6: 0.012204682 | C6: 350
A7: 2024-07-15 | B7: -0.0048638338 | C7: 170
A8: 2024-07-22 | B8: 0.032447298 | C8: 1391
A9: 2024-07-29 | B9: -0.0072526034 | C9: 160
A10: Instagram | B10: 0.64428596 | C10: 5104
A11: 2024-07-01 | B11: -0.0051814067 | C11: 226
A12: 2024-07-08 | B12: 0.29356437 | C12: 1757
A13: 2024-07-15 | B13: 0.12026393 | C13: 1960
A14: 2024-07-22 | B14: 0.0033330681 | C14: 508
A15: 2024-07-29 | B15: 0.23230601 | C15: 653
... A33: Grand Total | B33: 1 | C33: 16879

Sheet ad.spend Vs weekly growth
A1: New_Followers | B1: Unfollows | C1: Ad_Spend | D1: Weekly followers growth
A2: 1135 | B2: 88 | C2: 5904 | D2: =A2-B2 -> 1047
A3: 1312 | B3: 310 | C3: 9566 | D3: =A3-B3 -> 1002
A4: 584 | B4: 169 | C4: 26752 | D4: =A4-B4 -> 415
A5: 1535 | B5: 445 | C5: 30671 | D5: =A5-B5 -> 1090
A6: 656 | B6: 139 | C6: 9920 | D6: =A6-B6 -> 517
A7: 1697 | B7: 414 | C7: 7924 | D7: =A7-B7 -> 1283
A8: 436 | B8: 250 | C8: 8912 | D8: =A8-B8 -> 186
A9: 1197 | B9: 203 | C9: 21205 | D9: =A9-B9 -> 994
A10: 1048 | B10: 155 | C10: 11329 | D10: =A10-B10 -> 893
A11: 1753 | B11: 371 | C11: 46670 | D11: =A11-B11 -> 1382
A12: 1335 | B12: 40 | C12: 22482 | D12: =A12-B12 -> 1295
A13: 403 | B13: 66 | C13: 24313 | D13: =A13-B13 -> 337
... A201: 119 | B201: 456 | C201: 12174 | D201: =A201-B201 -> -337

Sheet Engagement Summary
A1: Week_Start_Date | B1: Platform | C1: New_Followers | D1: Unfollows | E1: Total_Followers | F1: Engagement_Rate | G1: Ad_Spend | H1: Old_followers | I1: Growth Rate | J1: weekly growth
A2: 2024-06-03 | B2: Instagram | C2: 1135 | D2: 88 | E2: 344084 | F2: 8.06 | G2: 5904 | H2: =E2-C2+D2 -> 343037 | I2: =(E2-H2)/H2 -> 0.0030521489 | J2: =C2-D2 -> 1047
A3: 2024-06-03 | B3: Facebook | C3: 1312 | D3: 310 | E3: 42654 | F3: 4.98 | G3: 9566 | H3: =E3-C3+D3 -> 41652 | I3: =(E3-H3)/H3 -> 0.024056468 | J3: =C3-D3 -> 1002
A4: 2024-06-03 | B4: Twitter | C4: 584 | D4: 169 | E4: 146834 | F4: 8.31 | G4: 26752 | H4: =E4-C4+D4 -> 146419 | I4: =(E4-H4)/H4 -> 0.0028343316 | J4: =C4-D4 -> 415
A5: 2024-06-03 | B5: YouTube | C5: 1535 | D5: 445 | E5: 395536 | F5: 4.11 | G5: 30671 | H5: =E5-C5+D5 -> 394446 | I5: =(E5-H5)/H5 -> 0.0027633694 | J5: =C5-D5 -> 1090
A6: 2024-06-10 | B6: Instagram | C6: 656 | D6: 139 | E6: 49157 | F6: 9.05 | G6: 9920 | H6: =E6-C6+D6 -> 48640 | I6: =(E6-H6)/H6 -> 0.010629112 | J6: =C6-D6 -> 517
A7: 2024-06-10 | B7: Facebook | C7: 1697 | D7: 414 | E7: 316555 | F7: 2.37 | G7: 7924 | H7: =E7-C7+D7 -> 315272 | I7: =(E7-H7)/H7 -> 0.0040695019 | J7: =C7-D7 -> 1283
A8: 2024-06-10 | B8: Twitter | C8: 436 | D8: 250 | E8: 254347 | F8: 4.01 | G8: 8912 | H8: =E8-C8+D8 -> 254161 | I8: =(E8-H8)/H8 -> 0.00073181959 | J8: =C8-D8 -> 186
A9: 2024-06-10 | B9: YouTube | C9: 1197 | D9: 203 | E9: 413878 | F9: 3.16 | G9: 21205 | H9: =E9-C9+D9 -> 412884 | I9: =(E9-H9)/H9 -> 0.0024074558 | J9: =C9-D9 -> 994
A10: 2024-06-17 | B10: Instagram | C10: 1048 | D10: 155 | E10: 456946 | F10: 2.46 | G10: 11329 | H10: =E10-C10+D10 -> 456053 | I10: =(E10-H10)/H10 -> 0.0019581057 | J10: =C10-D10 -> 893
A11: 2024-06-17 | B11: Facebook | C11: 1753 | D11: 371 | E11: 169496 | F11: 8.11 | G11: 46670 | H11: =E11-C11+D11 -> 168114 | I11: =(E11-H11)/H11 -> 0.0082206122 | J11: =C11-D11 -> 1382
A12: 2024-06-17 | B12: Twitter | C12: 1335 | D12: 40 | E12: 122732 | F12: 8.19 | G12: 22482 | H12: =E12-C12+D12 -> 121437 | I12: =(E12-H12)/H12 -> 0.010663966 | J12: =C12-D12 -> 1295
A13: 2024-06-17 | B13: YouTube | C13: 403 | D13: 66 | E13: 382851 | F13: 3.49 | G13: 24313 | H13: =E13-C13+D13 -> 382514 | I13: =(E13-H13)/H13 -> 0.00088101351 | J13: =C13-D13 -> 337
... A201: 2025-05-12 | B201: YouTube | C201: 119 | D201: 456 | E201: 82558 | F201: 6.81 | G201: 12174 | H201: =E201-C201+D201 -> 82895 | I201: =(E201-H201)/H201 -> -0.0040653839 | J201: =C201-D201 -> -337

Sheet Sheet7
A1: Growth Rate | B1: weekly growth
A2: ='Engagement Summary'!I2 -> 0.0030521489 | B2: ='Engagement Summary'!J2 -> 1047
A3: ='Engagement Summary'!I3 -> 0.024056468 | B3: ='Engagement Summary'!J3 -> 1002 | E3: maximum followers | F3: Identify the peak week of follower gain.
A4: ='Engagement Summary'!I4 -> 0.0028343316 | B4: ='Engagement Summary'!J4 -> 415 | E4: =MAX(B2:B201) -> 1881 | F4: =INDEX('Engagement Summary'!A2:A201,MATCH(MAX(Sheet7!B2:B201),Sheet7!B2:B201,)) -> 2025-05-05
A5: ='Engagement Summary'!I5 -> 0.0027633694 | B5: ='Engagement Summary'!J5 -> 1090
A6: ='Engagement Summary'!I6 -> 0.010629112 | B6: ='Engagement Summary'!J6 -> 517
A7: ='Engagement Summary'!I7 -> 0.0040695019 | B7: ='Engagement Summary'!J7 -> 1283
A8: ='Engagement Summary'!I8 -> 0.00073181959 | B8: ='Engagement Summary'!J8 -> 186 | E8: Platform which gain maximum followers
A9: ='Engagement Summary'!I9 -> 0.0024074558 | B9: ='Engagement Summary'!J9 -> 994 | E9: =INDEX('Engagement Summary'!B2:B201,MATCH(MAX(Sheet7!B2:B201),Sheet7!B2:B201,)) -> Instagram
A10: ='Engagement Summary'!I10 -> 0.0019581057 | B10: ='Engagement Summary'!J10 -> 893
A11: ='Engagement Summary'!I11 -> 0.0082206122 | B11: ='Engagement Summary'!J11 -> 1382
A12: ='Engagement Summary'!I12 -> 0.010663966 | B12: ='Engagement Summary'!J12 -> 1295
A13: ='Engagement Summary'!I13 -> 0.00088101351 | B13: ='Engagement Summary'!J13 -> 337
A14: ='Engagement Summary'!I14 -> 0.017953475 | B14: ='Engagement Summary'!J14 -> 629
A15: ='Engagement Summary'!I15 -> 0.067817259 | B15: ='Engagement Summary'!J15 -> 1670
A16: ='Engagement Summary'!I16 -> 0.0028059116 | B16: ='Engagement Summary'!J16 -> 835
A17: ='Engagement Summary'!I17 -> -0.00028852447 | B17: ='Engagement Summary'!J17 -> -123
A18: ='Engagement Summary'!I18 -> -0.00052184356 | B18: ='Engagement Summary'!J18 -> -219
A19: ='Engagement Summary'!I19 -> 0.00029096728 | B19: ='Engagement Summary'!J19 -> 64
A20: ='Engagement Summary'!I20 -> 0.0043223719 | B20: ='Engagement Summary'!J20 -> 1357
A21: ='Engagement Summary'!I21 -> 0.00080114802 | B21: ='Engagement Summary'!J21 -> 91
... A201: ='Engagement Summary'!I201 -> -0.0040653839 | B201: ='Engagement Summary'!J201 -> -337

Sheet Campaign Metadata (2)
A1: Campaign_Name | B1: Start_Date | C1: End_Date | D1: Objective | E1: Total_Budget | F1: Target_Platforms | G1: Primary_Hashtags
A2: CybertruckLaunch | B2: 45458 | C2: 45488 | D2: Product Awareness | E2: 150000 | F2: Instagram | G2: #EVRevolution
A3: CybertruckLaunch | B3: 45458 | C3: 45488 | D3: Product Awareness | E3: 150000 | F3: Facebook | G3: #EVRevolution
A4: CybertruckLaunch | B4: 45458 | C4: 45488 | D4: Product Awareness | E4: 150000 | F4: Instagram | G4: #TeslaCoInnovation
A5: CybertruckLaunch | B5: 45458 | C5: 45488 | D5: Product Awareness | E5: 150000 | F5: Facebook | G5: #TeslaCoInnovation
A6: ModelYCampaign | B6: 45566 | C6: 45596 | D6: Customer Engagement | E6: 200000 | F6: Instagram | G6: #AnytimeIsTeslaTime
A7: ModelYCampaign | B7: 45566 | C7: 45596 | D7: Customer Engagement | E7: 200000 | F7: YouTube | G7: #AnytimeIsTeslaTime
A8: FSDUpdate | B8: 45651 | C8: 45667 | D8: Vehicle Launch | E8: 250000 | F8: Facebook | G8: #SmoothLikeNitroTesla
A9: FSDUpdate | B9: 45651 | C9: 45667 | D9: Vehicle Launch | E9: 250000 | F9: Twitter | G9: #SmoothLikeNitroTesla
A10: SustainabilityDrive | B10: 45717 | C10: 45747 | D10: Community Growth | E10: 180000 | F10: Instagram | G10: #BetterWithTesla
A11: SustainabilityDrive | B11: 45717 | C11: 45747 | D11: Community Growth | E11: 180000 | F11: Twitter | G11: #BetterWithTesla
A12: SustainabilityDrive | B12: 45717 | C12: 45747 | D12: Community Growth | E12: 180000 | F12: Instagram | G12: #FutureOfDriving
A13: SustainabilityDrive | B13: 45717 | C13: 45747 | D13: Community Growth | E13: 180000 | F13: Twitter | G13: #FutureOfDriving

Sheet Campaign Metadata
A1: Campaign_Name | B1: Start_Date | C1: End_Date | D1: Objective | E1: Total_Budget | F1: Target_Platforms | G1: Primary_Hashtags
A2: CybertruckLaunch | B2: 2024-06-15 | C2: 2024-07-15 | D2: Product Awareness | E2: 150000 | F2: Instagram,Facebook | G2: #EVRevolution,#TeslaCoInnovation
A3: ModelYCampaign | B3: 2024-10-01 | C3: 2024-10-31 | D3: Customer Engagement | E3: 200000 | F3: Instagram,YouTube | G3: #AnytimeIsTeslaTime,
A4: FSDUpdate | B4: 2024-12-25 | C4: 2025-01-10 | D4: Vehicle Launch | E4: 250000 | F4: Facebook,Twitter | G4: #SmoothLikeNitroTesla
A5: SustainabilityDrive | B5: 2025-03-01 | C5: 2025-03-31 | D5: Community Growth | E5: 180000 | F5: Instagram,Twitter | G5: #BetterWithTesla,#FutureOfDriving
